Workbook

Sheet Vzor
C1: RX Auto, s.r.o. | E1: Nájemní smlouva č: | G1: =Data!C6 -> 0
C2: Aviatická 1092/8, 161 00 Praha | F2: tel: +420 725 293 527 (OV)
C3: IČO: 06044310 DIČ: CZ06044310 | F3: tel: +420 725 293 516 (PRG)
C4: info@rxauto.cz, www.rxauto.cz | F4: tel: +420 725 293 519
A5: 01 Nájemce (společnost) | E5: 07 Informace o rezervaci
A6: společnost | C6: IČ | E6: Agent | G6: číslo rez.
A7: =Data!A2 -> 0 | C7: =Data!B2 -> 0
A8: sídlo | E8: číslo voucheru/potvrzení | G8: skupina vozu
A9: =Data!D2 -> 0 | G9: RX
A10: kontakt | C10: DIČ | E10: 08 Informace o pronájmu
A11: =Data!E2 -> 0 | C11: =Data!C2 -> 0 | E11: od | F11: do | G11: délka (dní)
A12: 02 Nájemce (řidič) | E12: =Data!A6 -> 0 | F12: =Data!B6 -> 0 | G12: =F12-E12 -> 0
A13: jméno a příjmení | E13: prodloužení do
A14: =Data!A4 -> 0
A15: datum narození/RČ | C15: místo narození | E15: Místo vyzvednutí
A16: =Data!B4 -> 0 | E16: Praha LVH
A17: číslo OP/pasu | B17: datum vydání | C17: platnost | D17: země | E17: Místo vrácení
E18: Praha LVH
A19: č. řidičského p. | B19: datum vydání | C19: platnost | D19: země | E19: 09 Jistina
A21: trvalé bydliště
E22: 10 Souhrn plateb bez DPH
A23: korespondeční adresa | E23: nájemné | G23: měsíčně
F24: =Data!L6 -> 0 | G24: =Data!K6 -> 0
A25: email | C25: telefon
A26: =Data!E17 -> 0 | C26: -
A27: 03 Další řidič
A28: Jméno a příjmení | B28: č.ŘP | C28: od | D28: do
A30: Jméno a příjmení | B30: č.ŘP | C30: od | D30: do
E31: Celkem | G31: =Data!K6 -> 0
A32: 04 Vozidlo | E32: 11 Platba celkem s 21% sazbou DPH
A33: SPZ | B33: Značka a model | E33: Celkem | F33: =F31*1.21 -> 0
A34: =Data!F6 -> 0
E35: 12 Způsob platby
A37: stav km OUT | B37: Sjednaný nájezd kilometrů | E37: 13 Sjednané podmínky pronájmu
B38: =Data!I6 -> 0 | E38: V ceně nájmu je zahrnuto: daň silniční, rozhlasový poplatek, zákonné pojištění, havarijní pojištění se spoluúčastí 10% min. 10000 Kč, pojištění čelního skla se spoluúčastí 1000,-Kč, sezónní pneumatiky, silniční asistence,
A39: 05 Cena za kilometr nad sjednaný rámec
A40: cena za km | B40: 9,-Kč | C40: + 21% DPH
A41: 06 Náhradní vozidlo/výměna
A42: SPZ | B42: datum | C42: stav km | D42: palivo
A44: Nájemce potvrzuje, že obdržel kopii této Smlouvy, že si Smlouvu a Všeobecné obchodní podmínky přečetl, a že s nimi souhlasí. Nájemce potvrzuje stav vozidla, uvedený ve Smlouvě a předávacím protokolu. V případě platby kreditní kartou Nájemce potvrzuje svým podpisem souhlas s inkasem celé částky, včetně všech škod, způsobených na vozidle během doby trvání Pronájmu a dále správních poplatků, pokut a dodatečných poplatků. Nájemce přebírá odpovědnost za všechny dopravní přestupky, způsobené s vozidlem po dobu trvání Pronájmu.
...

Sheet Data
A1: FIRMA | B1: IČ | C1: DIČ | D1: Sídlo | E1: kontakt
A3: řidič (jméno, příjmení | B3: datum narození/RČ
A5: zacatek | B5: konec | C5: smlouva číslo/zakazka | F5: auto (typ, spz, vin) | I5: sjednaný nájezd | J5: K fakturaci | K5: interval (měsíčně/den/týden | L5: počet dní/měsíců
